Workbook

Sheet Carpetas
A1: Cliente | B1: Carpeta
A2: Almacen Amc Sas | B2: AMC
A3: Central De Maderas G&S S.A.S. | B3: Central de maderas
A4: Centro Comercial Y Empresarial Obelisco - P.H.- | B4: Obelisco
A5: Centro Comercial Y Empresarial Savanna Plaza Propiedad Horizontal | B5: Savanna Plaza
A6: Condominio Acanto P. H | B6: Acanto
A7: Congregación De Religiosas Hijas De Cristo Rey | B7: Cristo Rey
A8: Conjunto Residencial San Esteban Del Poblado P.H. | B8: San Esteban
A9: Cooperativa Antioqueña De Salud | B9: coopsana ips
A10: Ecoimagen Salud S.A.S | B10: Ecoimagen ips
A11: Edificio Torre Almagran Propiedad Horizontal | B11: Almagran
A12: Instituto Bolivariano (Ibes) | B12: instituto bolivariano (ibes)
... A27: Minigranja Solar El Son | B27: 0015 El Son

Sheet Diciembre
A1: Proyecto | B1: CLIENTE | C1: Inversionista | D1: Documento contable | E1: Ciudad | F1: Concepto | G1: Total | H1: Factura | I1: Link Carpeta General | J1: Codigo | L1: Generar | M1: Proyecto | N1: Carpeta proyecto | O1: Factura | Q1: Fecha de Firma | R1: 46029 | S1: Fecha periodo | T1: 01 al 31 de diciembre del 2025 | U1: consecutivo final | V1: 287
A2: Almacen Amc Sas | B2: ALMACEN AMC SAS | C2: Total | D2: Mandato | E2: Sincelejo | F2: Ingreso Bruto | G2: =SUMIFS('Diciembre Data'!C:C,'Diciembre Data'!A:A,B2,'Diciembre Data'!B:B,F2) -> 3807241.5 | H2: =VLOOKUP(B2,'Diciembre Data'!A:D,4,FALSE) -> UESP1325 | I2: AMC | J2: =V1 -> 287 | L2: FALSE | M2: Almacen Amc Sas | N2: AMC
A3: Almacen Amc Sas | B3: ALMACEN AMC SAS | C3: total | D3: Mandato | E3: Sincelejo | F3: Interes | G3: =SUMIFS('Diciembre Data'!C:C,'Diciembre Data'!A:A,B3,'Diciembre Data'!B:B,F3) -> 108024.99 | H3: =VLOOKUP(B3,'Diciembre Data'!A:D,4,FALSE) -> UESP1325 | I3: AMC | L3: FALSE | M3: Arcillas San Simon S.A.S. | N3: Arcillas San Simón
A4: Almacen Amc Sas | B4: ALMACEN AMC SAS | C4: total | D4: Mandato | E4: Sincelejo | F4: Valor a Pagar | G4: =G2+G3 -> 3915266.5 | H4: =VLOOKUP(B4,'Diciembre Data'!A:D,4,FALSE) -> UESP1325 | L4: FALSE | M4: Central De Maderas G&S S.A.S. | N4: Central de maderas
A5: Almacen Amc Sas | B5: ALMACEN AMC SAS | C5: Factura | D5: Factura | E5: Sincelejo | F5: Administración | G5: =G4*5% -> 195763.32 | H5: =VLOOKUP(B5,'Diciembre Data'!A:D,4,FALSE) -> UESP1325 | I5: AMC | L5: FALSE | M5: Centro Comercial Y Empresarial Obelisco - P.H.- | N5: Obelisco
A6: Almacen Amc Sas | B6: ALMACEN AMC SAS | C6: Factura | D6: Factura | E6: Sincelejo | F6: Total | G6: =G5 -> 195763.32 | H6: =VLOOKUP(B6,'Diciembre Data'!A:D,4,FALSE) -> UESP1325 | I6: AMC
A7: Arcillas San Simon S.A.S. | B7: ARCILLAS SAN SIMON S.A.S. | C7: Total | D7: Mandato | E7: El Zulia | F7: Ingreso Bruto | G7: =SUMIFS('Diciembre Data'!C:C,'Diciembre Data'!A:A,B7,'Diciembre Data'!B:B,F7) -> 0 | H7: =VLOOKUP(B7,'Diciembre Data'!A:D,4,FALSE) -> #N/A | I7: Arcillas San Simón | J7: =J2+1 -> 288 | L7: FALSE | M7: Condominio Acanto P. H | N7: Acanto
A8: Arcillas San Simon S.A.S. | B8: ARCILLAS SAN SIMON S.A.S. | C8: total | D8: Mandato | E8: El Zulia | F8: Interes | G8: =SUMIFS('Diciembre Data'!C:C,'Diciembre Data'!A:A,B8,'Diciembre Data'!B:B,F8) -> 0 | H8: =VLOOKUP(B8,'Diciembre Data'!A:D,4,FALSE) -> #N/A | I8: Arcillas San Simón | L8: FALSE | M8: Congregación De Religiosas Hijas De Cristo Rey | N8: Cristo Rey
A9: Arcillas San Simon S.A.S. | B9: ARCILLAS SAN SIMON S.A.S. | C9: total | D9: Mandato | E9: El Zulia | F9: Valor a Pagar | G9: =G8+G7 -> 0 | H9: =VLOOKUP(B9,'Diciembre Data'!A:D,4,FALSE) -> #N/A | L9: FALSE | M9: Conjunto Laureles Campestre Etapas I Ii Y Iii Ph | N9: Laureles Campestre
A10: Arcillas San Simon S.A.S. | B10: ARCILLAS SAN SIMON S.A.S. | C10: Factura | D10: Factura | E10: El Zulia | F10: Administración | G10: =G9*5% -> 0 | H10: =VLOOKUP(B10,'Diciembre Data'!A:D,4,FALSE) -> #N/A | L10: FALSE | M10: Conjunto Residencial San Esteban Del Poblado P.H. | N10: San Esteban
A11: Arcillas San Simon S.A.S. | B11: ARCILLAS SAN SIMON S.A.S. | C11: Factura | D11: Factura | E11: El Zulia | F11: Total | G11: =G10 -> 0 | H11: =VLOOKUP(B11,'Diciembre Data'!A:D,4,FALSE) -> #N/A | L11: FALSE | M11: Cooperativa Antioqueña De Salud | N11: coopsana ips
A12: Central De Maderas G&S S.A.S. | B12: CENTRAL DE MADERAS G&S S.A.S. | C12: Total | D12: Mandato | E12: Turbaná | F12: Ingreso Bruto | G12: =SUMIFS('Diciembre Data'!C:C,'Diciembre Data'!A:A,B12,'Diciembre Data'!B:B,F12) -> 3356632.7 | H12: =VLOOKUP(B12,'Diciembre Data'!A:D,4,FALSE) -> UESP1334 | I12: Central de maderas | J12: =J2+1 -> 288 | L12: FALSE | M12: Dual Cross S.A.S | N12: Cross Bisnes center
A13: Central De Maderas G&S S.A.S. | B13: CENTRAL DE MADERAS G&S S.A.S. | C13: total | D13: Mandato | E13: Turbaná | F13: Interes | G13: =SUMIFS('Diciembre Data'!C:C,'Diciembre Data'!A:A,B13,'Diciembre Data'!B:B,F13) -> 56978.08 | H13: =VLOOKUP(B13,'Diciembre Data'!A:D,4,FALSE) -> UESP1334 | I13: Central de maderas | L13: FALSE | M13: Ecoimagen Salud S.A.S | N13: Ecoimagen ips
A14: Central De Maderas G&S S.A.S. | B14: CENTRAL DE MADERAS G&S S.A.S. | C14: total | D14: Mandato | F14: Retención en la fuente | G14: =(G12+G13)*4% -> 136544.43 | H14: =VLOOKUP(B14,'Diciembre Data'!A:D,4,FALSE) -> UESP1334 | L14: FALSE | M14: Edificio Torre Almagran Propiedad Horizontal | N14: Almagran
A15: Central De Maderas G&S S.A.S. | B15: CENTRAL DE MADERAS G&S S.A.S. | C15: total | D15: Mandato | E15: Turbaná | F15: Valor a Pagar | G15: =G12+G13-G14 -> 3277066.3 | H15: =VLOOKUP(B15,'Diciembre Data'!A:D,4,FALSE) -> UESP1334 | L15: FALSE | M15: Instituto Bolivariano (Ibes) | N15: instituto bolivariano (ibes)
A16: Central De Maderas G&S S.A.S. | B16: CENTRAL DE MADERAS G&S S.A.S. | C16: Factura | D16: Factura | E16: Turbaná | F16: Administración | G16: =G15*5% -> 163853.32 | H16: =VLOOKUP(B16,'Diciembre Data'!A:D,4,FALSE) -> UESP1334 | L16: FALSE | M16: Los Coches | N16: Hotel los coches
A17: Central De Maderas G&S S.A.S. | B17: CENTRAL DE MADERAS G&S S.A.S. | C17: Factura | D17: Factura | E17: Turbaná | F17: Total | G17: =G16 -> 163853.32 | H17: =VLOOKUP(B17,'Diciembre Data'!A:D,4,FALSE) -> UESP1334 | L17: FALSE | M17: M.D.M. Cientifica S.A.S | N17: MDM Cientifica
A18: Centro Comercial Y Empresarial Obelisco - P.H.- | B18: CENTRO COMERCIAL Y EMPRESARIAL OBELISCO - P.H.- | C18: Total | D18: Mandato | E18: Medellín | F18: Ingreso Bruto | G18: =SUMIFS('Diciembre Data'!C:C,'Diciembre Data'!A:A,B18,'Diciembre Data'!B:B,F18) -> 5394120.8 | H18: =VLOOKUP(B18,'Diciembre Data'!A:D,4,FALSE) -> UESP1327 | I18: Obelisco | J18: =J12+1 -> 289 | L18: FALSE | M18: Polikem S.A.S | N18: Polikem
A19: Centro Comercial Y Empresarial Obelisco - P.H.- | B19: CENTRO COMERCIAL Y EMPRESARIAL OBELISCO - P.H.- | C19: total | D19: Mandato | E19: Medellín | F19: Interes | G19: =SUMIFS('Diciembre Data'!C:C,'Diciembre Data'!A:A,B19,'Diciembre Data'!B:B,F19) -> 0 | H19: =VLOOKUP(B19,'Diciembre Data'!A:D,4,FALSE) -> UESP1327 | I19: Obelisco | L19: FALSE | M19: Servicios Industriales Y Metalmecanicos Sas | N19: Seridme
A20: Centro Comercial Y Empresarial Obelisco - P.H.- | B20: CENTRO COMERCIAL Y EMPRESARIAL OBELISCO - P.H.- | C20: total | D20: Mandato | E20: Medellín | F20: Valor a Pagar | G20: =G19+G18 -> 5394120.8 | H20: =VLOOKUP(B20,'Diciembre Data'!A:D,4,FALSE) -> UESP1327 | L20: FALSE | M20: Sociedad Educativa Ngs Sas | N20: NGS
A21: Centro Comercial Y Empresarial Obelisco - P.H.- | B21: CENTRO COMERCIAL Y EMPRESARIAL OBELISCO - P.H.- | C21: Factura | D21: Factura | F21: Administración | G21: =G20*5% -> 269706.04 | H21: =VLOOKUP(B21,'Diciembre Data'!A:D,4,FALSE) -> UESP1327 | L21: FALSE | M21: Sociedad Medica Rionegro S.A. Somer S.A. | N21: Clinica Somer
A22: Centro Comercial Y Empresarial Obelisco - P.H.- | B22: CENTRO COMERCIAL Y EMPRESARIAL OBELISCO - P.H.- | C22: Factura | D22: Factura | F22: Total | G22: =G21 -> 269706.04 | H22: =VLOOKUP(B22,'Diciembre Data'!A:D,4,FALSE) -> UESP1327 | L22: FALSE | M22: The Pub S. A. S. | N22: Pola Del Pub
L23: FALSE | M23: Urbanizacion Arboleda De Castilla Propiedad Horizontal | N23: arboleda de castilla
A29: Condominio Acanto P. H | B29: CONDOMINIO ACANTO Ρ. Η | C29: Total | D29: Mandato | E29: Envigado | F29: Ingreso Bruto | G29: =SUMIFS('Diciembre Data'!C:C,'Diciembre Data'!A:A,B29,'Diciembre Data'!B:B,F29) -> 4790049.8 | H29: =VLOOKUP(B29,'Diciembre Data'!A:D,4,FALSE) -> UESP1323 | I29: Acanto | J29: =J18+1 -> 290
A30: Condominio Acanto P. H | B30: CONDOMINIO ACANTO Ρ. Η | C30: total | D30: Mandato | E30: Envigado | F30: Interes | G30: =SUMIFS('Diciembre Data'!C:C,'Diciembre Data'!A:A,B30,'Diciembre Data'!B:B,F30) -> 0 | H30: =VLOOKUP(B30,'Diciembre Data'!A:D,4,FALSE) -> UESP1323 | I30: Acanto
A31: Condominio Acanto P. H | B31: CONDOMINIO ACANTO Ρ. Η | C31: total | D31: Mandato | E31: Envigado | F31: Valor a Pagar | G31: =G30+G29 -> 4790049.8 | H31: =VLOOKUP(B31,'Diciembre Data'!A:D,4,FALSE) -> UESP1323
A32: Condominio Acanto P. H | B32: CONDOMINIO ACANTO Ρ. Η | C32: Factura | D32: Factura | F32: Administración | G32: =G31*5% -> 239502.49 | H32: =VLOOKUP(B32,'Diciembre Data'!A:D,4,FALSE) -> UESP1323
A33: Condominio Acanto P. H | B33: CONDOMINIO ACANTO Ρ. Η | C33: Factura | D33: Factura | F33: Total | G33: =G32 -> 239502.49 | H33: =VLOOKUP(B33,'Diciembre Data'!A:D,4,FALSE) -> UESP1323
A34: Congregación De Religiosas Hijas De Cristo Rey | B34: CONGREGACIÓN DE RELIGIOSAS HIJAS DE CRISTO REY | C34: Total | D34: Mandato | E34: Bogotá, D.C. | F34: Ingreso Bruto | G34: =SUMIFS('Diciembre Data'!C:C,'Diciembre Data'!A:A,B34,'Diciembre Data'!B:B,F34) -> 2680876.5 | H34: =VLOOKUP(B34,'Diciembre Data'!A:D,4,FALSE) -> UESP1336 | I34: Cristo Rey | J34: =J29+1 -> 291
A35: Congregación De Religiosas Hijas De Cristo Rey | B35: CONGREGACIÓN DE RELIGIOSAS HIJAS DE CRISTO REY | C35: total | D35: Mandato | E35: Bogotá, D.C. | F35: Interes | G35: =SUMIFS('Diciembre Data'!C:C,'Diciembre Data'!A:A,B35,'Diciembre Data'!B:B,F35) -> 16521.27 | H35: =VLOOKUP(B35,'Diciembre Data'!A:D,4,FALSE) -> UESP1336 | I35: Cristo Rey
A36: Congregación De Religiosas Hijas De Cristo Rey | B36: CONGREGACIÓN DE RELIGIOSAS HIJAS DE CRISTO REY | C36: total | D36: Mandato | E36: Bogotá, D.C. | F36: Valor a Pagar | G36: =G35+G34 -> 2697397.8 | H36: =VLOOKUP(B36,'Diciembre Data'!A:D,4,FALSE) -> UESP1336
A37: Congregación De Religiosas Hijas De Cristo Rey | B37: CONGREGACIÓN DE RELIGIOSAS HIJAS DE CRISTO REY | C37: Factura | D37: Factura | F37: Administración | G37: =G36*5% -> 134869.89 | H37: =VLOOKUP(B37,'Diciembre Data'!A:D,4,FALSE) -> UESP1336
A38: Congregación De Religiosas Hijas De Cristo Rey | B38: CONGREGACIÓN DE RELIGIOSAS HIJAS DE CRISTO REY | C38: Factura | D38: Factura | F38: Total | G38: =G37 -> 134869.89 | H38: =VLOOKUP(B38,'Diciembre Data'!A:D,4,FALSE) -> UESP1336
A39: Conjunto Laureles Campestre Etapas I Ii Y Iii Ph | B39: CONJUNTO LAURELES CAMPESTRE ETAPAS I II Y III | C39: Total | D39: Mandato | E39: Medellín | F39: Ingreso Bruto | G39: =SUMIFS('Diciembre Data'!C:C,'Diciembre Data'!A:A,B39,'Diciembre Data'!B:B,F39) -> 12077510 | H39: =VLOOKUP(B39,'Diciembre Data'!A:D,4,FALSE) -> UESP1339 | I39: Laureles Campestre | J39: =J34+1 -> 292
A40: Conjunto Laureles Campestre Etapas I Ii Y Iii Ph | B40: CONJUNTO LAURELES CAMPESTRE ETAPAS I II Y III | C40: total | D40: Mandato | E40: Medellín | F40: Interes | G40: =SUMIFS('Diciembre Data'!C:C,'Diciembre Data'!A:A,B40,'Diciembre Data'!B:B,F40) -> 75767.13 | H40: =VLOOKUP(B40,'Diciembre Data'!A:D,4,FALSE) -> UESP1339 | I40: Laureles Campestre
A41: Conjunto Laureles Campestre Etapas I Ii Y Iii Ph | B41: CONJUNTO LAURELES CAMPESTRE ETAPAS I II Y III | C41: total | D41: Mandato | E41: Medellín | F41: Valor a Pagar | G41: =G40+G39 -> 12153277 | H41: =VLOOKUP(B41,'Diciembre Data'!A:D,4,FALSE) -> UESP1339
A42: Conjunto Laureles Campestre Etapas I Ii Y Iii Ph | B42: CONJUNTO LAURELES CAMPESTRE ETAPAS I II Y III | C42: Factura | D42: Factura | F42: Administración | G42: =G41*5% -> 607663.87 | H42: =VLOOKUP(B42,'Diciembre Data'!A:D,4,FALSE) -> UESP1339
A43: Conjunto Laureles Campestre Etapas I Ii Y Iii Ph | B43: CONJUNTO LAURELES CAMPESTRE ETAPAS I II Y III | C43: Factura | D43: Factura | F43: Total | G43: =G42 -> 607663.87 | H43: =VLOOKUP(B43,'Diciembre Data'!A:D,4,FALSE) -> UESP1339
A44: Conjunto Residencial San Esteban Del Poblado P.H. | B44: CONJUNTO RESIDENCIAL SAN ESTEBAN DEL POBLADO P.H. | C44: Total | D44: Mandato | E44: Medellín | F44: Ingreso Bruto | G44: =SUMIFS('Diciembre Data'!C:C,'Diciembre Data'!A:A,B44,'Diciembre Data'!B:B,F44) -> 1943033.4 | H44: =VLOOKUP(B44,'Diciembre Data'!A:D,4,FALSE) -> UESP1329 | I44: San Esteban | J44: =J39+1 -> 293
A45: Conjunto Residencial San Esteban Del Poblado P.H. | B45: CONJUNTO RESIDENCIAL SAN ESTEBAN DEL POBLADO P.H. | C45: total | D45: Mandato | E45: Medellín | F45: Interes | G45: =SUMIFS('Diciembre Data'!C:C,'Diciembre Data'!A:A,B45,'Diciembre Data'!B:B,F45) -> 0 | H45: =VLOOKUP(B45,'Diciembre Data'!A:D,4,FALSE) -> UESP1329 | I45: San Esteban
...

Sheet Diciembre Data
A1: Proyecto | B1: Concepto | C1: Total | D1: Factura
A2: SOCIEDAD MEDICA RIONEGRO S.A. SOMER S.A. | B2: Ingreso Bruto | C2: 9301995.2 | D2: UESP1320
A3: SOCIEDAD MEDICA RIONEGRO S.A. SOMER S.A. | B3: Interes | C3: 0 | D3: UESP1320
A4: SOCIEDAD MEDICA RIONEGRO S.A. SOMER S.A. | B4: Valor a Pagar | C4: 9301995.2 | D4: UESP1320
A5: URBANIZACION ARBOLEDA DE CASTILLA PROPIEDAD HORIZONTAL | B5: Ingreso Bruto | C5: 2721813.6 | D5: UESP1321
A6: URBANIZACION ARBOLEDA DE CASTILLA PROPIEDAD HORIZONTAL | B6: Interes | C6: 16447.24 | D6: UESP1321
A7: URBANIZACION ARBOLEDA DE CASTILLA PROPIEDAD HORIZONTAL | B7: Valor a Pagar | C7: 2738260.9 | D7: UESP1321
A8: ECOIMAGEN SALUD S.A.S | B8: Ingreso Bruto | C8: 1569583.4 | D8: UESP1322
A9: ECOIMAGEN SALUD S.A.S | B9: Interes | C9: 12999.13 | D9: UESP1322
A10: ECOIMAGEN SALUD S.A.S | B10: Valor a Pagar | C10: 1582582.6 | D10: UESP1322
A11: CONDOMINIO ACANTO Ρ. Η | B11: Ingreso Bruto | C11: 4790049.8 | D11: UESP1323
A12: CONDOMINIO ACANTO Ρ. Η | B12: Interes | C12: 0 | D12: UESP1323
A13: CONDOMINIO ACANTO Ρ. Η | B13: Valor a Pagar | C13: 4790049.8 | D13: UESP1323
... A60: CONJUNTO LAURELES CAMPESTRE ETAPAS I II Y III | B60: Interes | C60: 75767.13 | D60: UESP1339
A61: CONJUNTO LAURELES CAMPESTRE ETAPAS I II Y III | B61: Valor a Pagar | C61: =C59+C60 -> 12153277 | D61: UESP1339

Sheet Poliza
A1: Proyecto | C1: Inversionista | D1: Documento contable | E1: Ciudad | F1: Concepto | G1: Total | H1: Asiento contable | I1: Link Carpeta General | J1: Codigo | L1: Generar | M1: Proyecto | Q1: Fecha de Firma | R1: 45994 | S1: Fecha periodo | T1: 01 al 30 de noviembre del 2025 | U1: consecutivo final | V1: 527
A2: Arcillas San Simon S.A.S. | B2: ARCILLAS SAN SIMON S.A.S. | C2: Total | D2: Mandato | E2: El Zulia | F2: Poliza | G2: 1657631.9 | I2: Arcillas San Simón | J2: =V1 -> 527 | L2: TRUE | M2: Arcillas San Simon S.A.S.
A3: Arcillas San Simon S.A.S. | B3: ARCILLAS SAN SIMON S.A.S. | C3: Total | D3: Mandato | F3: IVA | G3: =G2*19% -> 314950.07 | L3: TRUE | M3: Centro Comercial Y Empresarial Obelisco - P.H.-
A4: Arcillas San Simon S.A.S. | B4: ARCILLAS SAN SIMON S.A.S. | C4: total | D4: Mandato | E4: El Zulia | F4: Valor a Pagar | G4: =G2+G3 -> 1972582 | L4: TRUE | M4: Centro Comercial Y Empresarial Savanna Plaza Propiedad Horizontal
A5: Centro Comercial Y Empresarial Obelisco - P.H.- | B5: CENTRO COMERCIAL Y EMPRESARIAL OBELISCO - P.H.- | C5: Total | D5: Mandato | E5: Medellín | F5: Poliza | G5: 1275226.9 | I5: Obelisco | J5: =J2+1 -> 528 | L5: TRUE | M5: Condominio Acanto P. H
A6: Centro Comercial Y Empresarial Obelisco - P.H.- | B6: CENTRO COMERCIAL Y EMPRESARIAL OBELISCO - P.H.- | C6: Total | D6: Mandato | F6: IVA | G6: =G5*19% -> 242293.11 | L6: TRUE | M6: Conjunto Residencial San Esteban Del Poblado P.H.
A7: Centro Comercial Y Empresarial Obelisco - P.H.- | B7: CENTRO COMERCIAL Y EMPRESARIAL OBELISCO - P.H.- | C7: total | D7: Mandato | E7: Medellín | F7: Valor a Pagar | G7: =G5+G6 -> 1517520 | L7: TRUE | M7: Cooperativa Antioqueña De Salud
A8: Centro Comercial Y Empresarial Savanna Plaza Propiedad Horizontal | B8: CENTRO COMERCIAL Y EMPRESARIAL SAVANNA PLAZA PROPIEDAD HORIZONTAL | C8: Total | D8: Mandato | E8: Rionegro | F8: Poliza | G8: 538967.23 | I8: Savanna Plaza | J8: =J5+1 -> 529 | L8: TRUE | M8: Dual Cross S.A.S
A9: Centro Comercial Y Empresarial Savanna Plaza Propiedad Horizontal | B9: CENTRO COMERCIAL Y EMPRESARIAL SAVANNA PLAZA PROPIEDAD HORIZONTAL | C9: Total | D9: Mandato | F9: IVA | G9: =G8*19% -> 102403.77 | L9: TRUE | M9: Ecoimagen Salud S.A.S
A10: Centro Comercial Y Empresarial Savanna Plaza Propiedad Horizontal | B10: CENTRO COMERCIAL Y EMPRESARIAL SAVANNA PLAZA PROPIEDAD HORIZONTAL | C10: total | D10: Mandato | E10: Rionegro | F10: Valor a Pagar | G10: =G8+G9 -> 641371 | L10: TRUE | M10: Edificio Torre Almagran Propiedad Horizontal
A11: Condominio Acanto P. H | B11: CONDOMINIO ACANTO Ρ. Η | C11: Total | D11: Mandato | E11: Envigado | F11: Poliza | G11: 1200235.3 | I11: Acanto | J11: =J8+1 -> 530 | L11: TRUE | M11: Los Coches
A12: Condominio Acanto P. H | B12: CONDOMINIO ACANTO Ρ. Η | C12: Total | D12: Mandato | F12: IVA | G12: =G11*19% -> 228044.71 | L12: TRUE | M12: M.D.M. Cientifica S.A.S
A13: Condominio Acanto P. H | B13: CONDOMINIO ACANTO Ρ. Η | C13: total | D13: Mandato | E13: Envigado | F13: Valor a Pagar | G13: =G11+G12 -> 1428280 | L13: TRUE | M13: Polikem S.A.S
A14: Conjunto Residencial San Esteban Del Poblado P.H. | B14: CONJUNTO RESIDENCIAL SAN ESTEBAN DEL POBLADO P.H. | C14: Total | D14: Mandato | E14: Medellín | F14: Poliza | G14: 689048.74 | I14: San Esteban | J14: =J11+1 -> 531 | L14: TRUE | M14: Servicios Industriales Y Metalmecanicos Sas
A15: Conjunto Residencial San Esteban Del Poblado P.H. | B15: CONJUNTO RESIDENCIAL SAN ESTEBAN DEL POBLADO P.H. | C15: Total | D15: Mandato | F15: IVA | G15: =G14*19% -> 130919.26 | L15: TRUE | M15: Sociedad Educativa Ngs Sas
A16: Conjunto Residencial San Esteban Del Poblado P.H. | B16: CONJUNTO RESIDENCIAL SAN ESTEBAN DEL POBLADO P.H. | C16: total | D16: Mandato | E16: Medellín | F16: Valor a Pagar | G16: =G15+G14 -> 819968 | L16: TRUE | M16: Sociedad Medica Rionegro S.A. Somer S.A.
A17: Cooperativa Antioqueña De Salud | B17: COOPERATIVA ANTIOQUEÑA DE SALUD | C17: Total | D17: Mandato | E17: Medellín | F17: Poliza | G17: 448324.37 | I17: coopsana ips | J17: =J14+1 -> 532 | L17: TRUE | M17: The Pub S. A. S.
A18: Cooperativa Antioqueña De Salud | B18: COOPERATIVA ANTIOQUEÑA DE SALUD | C18: Total | D18: Mandato | F18: IVA | G18: =G17*19% -> 85181.63 | L18: TRUE | M18: Gimnasio San Angelo
A19: Cooperativa Antioqueña De Salud | B19: COOPERATIVA ANTIOQUEÑA DE SALUD | C19: Total | D19: Mandato | E19: Medellín | F19: Valor a Pagar | G19: =G18+G17 -> 533506
A20: Dual Cross S.A.S | B20: DUAL CROSS S.A.S | C20: Total | D20: Mandato | E20: Medellín | F20: Poliza | G20: 680227.73 | I20: Cross Bisnes center | J20: =J17+1 -> 533
A21: Dual Cross S.A.S | B21: DUAL CROSS S.A.S | C21: Total | D21: Mandato | F21: IVA | G21: =G20*19% -> 129243.27
A22: Dual Cross S.A.S | B22: DUAL CROSS S.A.S | C22: total | D22: Mandato | E22: Medellín | F22: Valor a Pagar | G22: =G21+G20 -> 809471
A23: Ecoimagen Salud S.A.S | B23: ECOIMAGEN SALUD S.A.S | C23: Total | D23: Mandato | E23: Cúcuta | F23: Poliza | G23: 422515.97 | I23: Ecoimagen ips | J23: =J20+1 -> 534
A24: Ecoimagen Salud S.A.S | B24: ECOIMAGEN SALUD S.A.S | C24: Total | D24: Mandato | F24: IVA | G24: =G23*19% -> 80278.034
A25: Ecoimagen Salud S.A.S | B25: ECOIMAGEN SALUD S.A.S | C25: total | D25: Mandato | E25: Cúcuta | F25: Valor a Pagar | G25: =G24+G23 -> 502794
A26: Edificio Torre Almagran Propiedad Horizontal | B26: EDIFICIO TORRE ALMAGRAN PROPIEDAD HORIZONTAL | C26: Total | D26: Mandato | E26: Medellín | F26: Poliza | G26: 447405.04 | I26: Almagran | J26: =J23+1 -> 535
A27: Edificio Torre Almagran Propiedad Horizontal | B27: EDIFICIO TORRE ALMAGRAN PROPIEDAD HORIZONTAL | C27: Total | D27: Mandato | F27: IVA | G27: =G26*19% -> 85006.958
A28: Edificio Torre Almagran Propiedad Horizontal | B28: EDIFICIO TORRE ALMAGRAN PROPIEDAD HORIZONTAL | C28: total | D28: Mandato | E28: Medellín | F28: Valor a Pagar | G28: =G27+G26 -> 532412
A29: Los Coches | B29: CORREA TOBON ALBERTO DE JESUS | C29: Total | D29: Mandato | E29: Montelíbano | F29: Poliza | G29: 426730.25 | I29: Hotel los coches | J29: =J26+1 -> 536
A30: Los Coches | B30: CORREA TOBON ALBERTO DE JESUS | C30: Total | D30: Mandato | F30: IVA | G30: =G29*19% -> 81078.747
A31: Los Coches | B31: CORREA TOBON ALBERTO DE JESUS | C31: total | D31: Mandato | E31: Montelíbano | F31: Valor a Pagar | G31: =G30+G29 -> 507809
A32: M.D.M. Cientifica S.A.S | B32: M.D.M. CIENTIFICA S.A.S | C32: Total | D32: Mandato | E32: Medellín | F32: Poliza | G32: 625722.69 | I32: MDM Cientifica | J32: =J29+1 -> 537
A33: M.D.M. Cientifica S.A.S | B33: M.D.M. CIENTIFICA S.A.S | C33: Total | D33: Mandato | F33: IVA | G33: =G32*19% -> 118887.31
A34: M.D.M. Cientifica S.A.S | B34: M.D.M. CIENTIFICA S.A.S | C34: total | D34: Mandato | E34: Medellín | F34: Valor a Pagar | G34: =G33+G32 -> 744610
A35: Polikem S.A.S | B35: POLIKEM S.A.S | C35: Total | D35: Mandato | E35: Rionegro | F35: Poliza | G35: 433598.32 | I35: Polikem | J35: =J32+1 -> 538
A36: Polikem S.A.S | B36: POLIKEM S.A.S | C36: Total | D36: Mandato | F36: IVA | G36: =G35*19% -> 82383.681
A37: Polikem S.A.S | B37: POLIKEM S.A.S | C37: total | D37: Mandato | E37: Rionegro | F37: Valor a Pagar | G37: =G36+G35 -> 515982
A38: Servicios Industriales Y Metalmecanicos Sas | B38: SERVICIOS INDUSTRIALES Y METALMECANICOS SAS | C38: Total | D38: Mandato | E38: Cartagena De Indias | F38: Poliza | G38: 654646.22 | I38: Seridme | J38: =J35+1 -> 539
A39: Servicios Industriales Y Metalmecanicos Sas | B39: SERVICIOS INDUSTRIALES Y METALMECANICOS SAS | C39: Total | D39: Mandato | F39: IVA | G39: =G38*19% -> 124382.78
A40: Servicios Industriales Y Metalmecanicos Sas | B40: SERVICIOS INDUSTRIALES Y METALMECANICOS SAS | C40: total | D40: Mandato | E40: Cartagena De Indias | F40: Valor a Pagar | G40: =G39+G38 -> 779029
...

Sheet Enero
A1: Proyecto | B1: CLIENTE | C1: Inversionista | D1: Documento contable | E1: Ciudad | F1: Concepto | G1: Total | H1: Factura | I1: Link Carpeta General | J1: Codigo | L1: Generar | M1: Proyecto | N1: Carpeta proyecto | O1: Factura | Q1: Fecha de Firma | R1: 46057 | S1: Fecha periodo | T1: 01 al 31 de enero del 2025 | U1: consecutivo final | V1: 287
A2: Almacen Amc Sas | B2: ALMACEN AMC SAS | C2: Total | D2: Mandato | E2: Sincelejo | F2: Ingreso Bruto | G2: =SUMIFS('Enero Data'!C:C,'Enero Data'!A:A,B2,'Enero Data'!B:B,F2) -> 4095983.8 | H2: =VLOOKUP(B2,'Enero Data'!A:D,4,FALSE) -> UESP1422 | I2: AMC | J2: 405 | L2: FALSE | M2: Almacen Amc Sas | N2: AMC
A3: Almacen Amc Sas | B3: ALMACEN AMC SAS | C3: total | D3: Mandato | E3: Sincelejo | F3: Interes | G3: =SUMIFS('Enero Data'!C:C,'Enero Data'!A:A,B3,'Enero Data'!B:B,F3) -> 88460.21 | H3: =VLOOKUP(B3,'Enero Data'!A:D,4,FALSE) -> UESP1422 | I3: AMC | L3: FALSE | M3: Arcillas San Simon S.A.S. | N3: Arcillas San Simón
A4: Almacen Amc Sas | B4: ALMACEN AMC SAS | C4: total | D4: Mandato | E4: Sincelejo | F4: Valor a Pagar | G4: =G2+G3 -> 4184444 | H4: =VLOOKUP(B4,'Enero Data'!A:D,4,FALSE) -> UESP1422 | L4: FALSE | M4: Central De Maderas G&S S.A.S. | N4: Central de maderas
A5: Almacen Amc Sas | B5: ALMACEN AMC SAS | C5: Factura | D5: Factura | E5: Sincelejo | F5: Administración | G5: =G4*5% -> 209222.2 | H5: =VLOOKUP(B5,'Enero Data'!A:D,4,FALSE) -> UESP1422 | I5: AMC | L5: FALSE | M5: Centro Comercial Y Empresarial Obelisco - P.H.- | N5: Obelisco
A6: Almacen Amc Sas | B6: ALMACEN AMC SAS | C6: Factura | D6: Factura | E6: Sincelejo | F6: Total | G6: =G5 -> 209222.2 | H6: =VLOOKUP(B6,'Enero Data'!A:D,4,FALSE) -> UESP1422 | I6: AMC | L6: FALSE | M6: Condominio Acanto P. H | N6: Acanto
A7: Arcillas San Simon S.A.S. | B7: ARCILLAS SAN SIMON S.A.S. | C7: Total | D7: Mandato | E7: El Zulia | F7: Ingreso Bruto | G7: =SUMIFS('Enero Data'!C:C,'Enero Data'!A:A,B7,'Enero Data'!B:B,F7) -> 0 | H7: =VLOOKUP(B7,'Enero Data'!A:D,4,FALSE) -> #N/A | I7: Arcillas San Simón | J7: =J2 -> 405 | L7: FALSE | M7: Congregación De Religiosas Hijas De Cristo Rey | N7: Cristo Rey
A8: Arcillas San Simon S.A.S. | B8: ARCILLAS SAN SIMON S.A.S. | C8: total | D8: Mandato | E8: El Zulia | F8: Interes | G8: =SUMIFS('Enero Data'!C:C,'Enero Data'!A:A,B8,'Enero Data'!B:B,F8) -> 0 | H8: =VLOOKUP(B8,'Enero Data'!A:D,4,FALSE) -> #N/A | I8: Arcillas San Simón | L8: FALSE | M8: Conjunto Laureles Campestre Etapas I Ii Y Iii Ph | N8: Laureles Campestre
A9: Arcillas San Simon S.A.S. | B9: ARCILLAS SAN SIMON S.A.S. | C9: total | D9: Mandato | E9: El Zulia | F9: Valor a Pagar | G9: =G8+G7 -> 0 | H9: =VLOOKUP(B9,'Enero Data'!A:D,4,FALSE) -> #N/A | L9: FALSE | M9: Conjunto Residencial San Esteban Del Poblado P.H. | N9: San Esteban
A10: Arcillas San Simon S.A.S. | B10: ARCILLAS SAN SIMON S.A.S. | C10: Factura | D10: Factura | E10: El Zulia | F10: Administración | G10: =G9*5% -> 0 | H10: =VLOOKUP(B10,'Enero Data'!A:D,4,FALSE) -> #N/A | L10: FALSE | M10: Cooperativa Antioqueña De Salud | N10: coopsana ips
A11: Arcillas San Simon S.A.S. | B11: ARCILLAS SAN SIMON S.A.S. | C11: Factura | D11: Factura | E11: El Zulia | F11: Total | G11: =G10 -> 0 | H11: =VLOOKUP(B11,'Enero Data'!A:D,4,FALSE) -> #N/A | L11: FALSE | M11: Dual Cross S.A.S | N11: Cross Bisnes center
A12: Central De Maderas G&S S.A.S. | B12: CENTRAL DE MADERAS G&S S.A.S. | C12: Total | D12: Mandato | E12: Turbaná | F12: Ingreso Bruto | G12: =SUMIFS('Enero Data'!C:C,'Enero Data'!A:A,B12,'Enero Data'!B:B,F12) -> 2716852.4 | H12: =VLOOKUP(B12,'Enero Data'!A:D,4,FALSE) -> UESP1433 | I12: Central de maderas | J12: =J2+1 -> 406 | L12: FALSE | M12: Ecoimagen Salud S.A.S | N12: Ecoimagen ips
A13: Central De Maderas G&S S.A.S. | B13: CENTRAL DE MADERAS G&S S.A.S. | C13: total | D13: Mandato | E13: Turbaná | F13: Interes | G13: =SUMIFS('Enero Data'!C:C,'Enero Data'!A:A,B13,'Enero Data'!B:B,F13) -> 4102.6 | H13: =VLOOKUP(B13,'Enero Data'!A:D,4,FALSE) -> UESP1433 | I13: Central de maderas | L13: FALSE | M13: Edificio Torre Almagran Propiedad Horizontal | N13: Almagran
A14: Central De Maderas G&S S.A.S. | B14: CENTRAL DE MADERAS G&S S.A.S. | C14: total | D14: Mandato | F14: Retención en la fuente | G14: =(G12+G13)*4% -> 108838.2 | H14: =VLOOKUP(B14,'Enero Data'!A:D,4,FALSE) -> UESP1433 | L14: FALSE | M14: Instituto Bolivariano (Ibes) | N14: instituto bolivariano (ibes)
A15: Central De Maderas G&S S.A.S. | B15: CENTRAL DE MADERAS G&S S.A.S. | C15: total | D15: Mandato | E15: Turbaná | F15: Valor a Pagar | G15: =G12+G13-G14 -> 2612116.8 | H15: =VLOOKUP(B15,'Enero Data'!A:D,4,FALSE) -> UESP1433 | L15: FALSE | M15: Los Coches | N15: Hotel los coches
A16: Central De Maderas G&S S.A.S. | B16: CENTRAL DE MADERAS G&S S.A.S. | C16: Factura | D16: Factura | E16: Turbaná | F16: Administración | G16: =G15*5% -> 130605.84 | H16: =VLOOKUP(B16,'Enero Data'!A:D,4,FALSE) -> UESP1433 | L16: FALSE | M16: M.D.M. Cientifica S.A.S | N16: MDM Cientifica
A17: Central De Maderas G&S S.A.S. | B17: CENTRAL DE MADERAS G&S S.A.S. | C17: Factura | D17: Factura | E17: Turbaná | F17: Total | G17: =G16 -> 130605.84 | H17: =VLOOKUP(B17,'Enero Data'!A:D,4,FALSE) -> UESP1433 | L17: FALSE | M17: Polikem S.A.S | N17: Polikem
A18: Centro Comercial Y Empresarial Obelisco - P.H.- | B18: CENTRO COMERCIAL Y EMPRESARIAL OBELISCO -P.H.- | C18: Total | D18: Mandato | E18: Medellín | F18: Ingreso Bruto | G18: =SUMIFS('Enero Data'!C:C,'Enero Data'!A:A,B18,'Enero Data'!B:B,F18) -> 4906552.8 | H18: =VLOOKUP(B18,'Enero Data'!A:D,4,FALSE) -> UESP1424 | I18: Obelisco | J18: =J12+1 -> 407 | L18: FALSE | M18: Servicios Industriales Y Metalmecanicos Sas | N18: Seridme
A19: Centro Comercial Y Empresarial Obelisco - P.H.- | B19: CENTRO COMERCIAL Y EMPRESARIAL OBELISCO -P.H.- | C19: total | D19: Mandato | E19: Medellín | F19: Interes | G19: =SUMIFS('Enero Data'!C:C,'Enero Data'!A:A,B19,'Enero Data'!B:B,F19) -> 0 | H19: =VLOOKUP(B19,'Enero Data'!A:D,4,FALSE) -> UESP1424 | I19: Obelisco | L19: FALSE | M19: Sociedad Educativa Ngs Sas | N19: NGS
A20: Centro Comercial Y Empresarial Obelisco - P.H.- | B20: CENTRO COMERCIAL Y EMPRESARIAL OBELISCO -P.H.- | C20: total | D20: Mandato | E20: Medellín | F20: Valor a Pagar | G20: =G19+G18 -> 4906552.8 | H20: =VLOOKUP(B20,'Enero Data'!A:D,4,FALSE) -> UESP1424 | L20: TRUE | M20: Sociedad Medica Rionegro S.A. Somer S.A. | N20: Clinica Somer
A21: Centro Comercial Y Empresarial Obelisco - P.H.- | B21: CENTRO COMERCIAL Y EMPRESARIAL OBELISCO -P.H.- | C21: Factura | D21: Factura | F21: Administración | G21: =G20*5% -> 245327.64 | H21: =VLOOKUP(B21,'Enero Data'!A:D,4,FALSE) -> UESP1424 | L21: FALSE | M21: The Pub S. A. S. | N21: Pola Del Pub
A22: Centro Comercial Y Empresarial Obelisco - P.H.- | B22: CENTRO COMERCIAL Y EMPRESARIAL OBELISCO -P.H.- | C22: Factura | D22: Factura | F22: Total | G22: =G21 -> 245327.64 | H22: =VLOOKUP(B22,'Enero Data'!A:D,4,FALSE) -> UESP1424 | L22: TRUE | M22: Urbanizacion Arboleda De Castilla Propiedad Horizontal | N22: arboleda de castilla
A23: Condominio Acanto P. H | B23: CONDOMINIO ACANTO Ρ. Η | C23: Total | D23: Mandato | E23: Envigado | F23: Ingreso Bruto | G23: =SUMIFS('Enero Data'!C:C,'Enero Data'!A:A,B23,'Enero Data'!B:B,F23) -> 4209142.2 | H23: =VLOOKUP(B23,'Enero Data'!A:D,4,FALSE) -> UESP1420 | I23: Acanto | J23: =J18+1 -> 408
A24: Condominio Acanto P. H | B24: CONDOMINIO ACANTO Ρ. Η | C24: total | D24: Mandato | E24: Envigado | F24: Interes | G24: =SUMIFS('Enero Data'!C:C,'Enero Data'!A:A,B24,'Enero Data'!B:B,F24) -> 0 | H24: =VLOOKUP(B24,'Enero Data'!A:D,4,FALSE) -> UESP1420 | I24: Acanto
A25: Condominio Acanto P. H | B25: CONDOMINIO ACANTO Ρ. Η | C25: total | D25: Mandato | E25: Envigado | F25: Valor a Pagar | G25: =G24+G23 -> 4209142.2 | H25: =VLOOKUP(B25,'Enero Data'!A:D,4,FALSE) -> UESP1420
A26: Condominio Acanto P. H | B26: CONDOMINIO ACANTO Ρ. Η | C26: Factura | D26: Factura | F26: Administración | G26: =G25*5% -> 210457.11 | H26: =VLOOKUP(B26,'Enero Data'!A:D,4,FALSE) -> UESP1420
A27: Condominio Acanto P. H | B27: CONDOMINIO ACANTO Ρ. Η | C27: Factura | D27: Factura | F27: Total | G27: =G26 -> 210457.11 | H27: =VLOOKUP(B27,'Enero Data'!A:D,4,FALSE) -> UESP1420
A28: Congregación De Religiosas Hijas De Cristo Rey | B28: CONGREGACIÓN DE RELIGIOSAS HIJAS DE CRISTO REY | C28: Total | D28: Mandato | E28: Bogotá, D.C. | F28: Ingreso Bruto | G28: =SUMIFS('Enero Data'!C:C,'Enero Data'!A:A,B28,'Enero Data'!B:B,F28) -> 2372766.8 | H28: =VLOOKUP(B28,'Enero Data'!A:D,4,FALSE) -> UESP1416 | I28: Cristo Rey | J28: =J23+1 -> 409
A29: Congregación De Religiosas Hijas De Cristo Rey | B29: CONGREGACIÓN DE RELIGIOSAS HIJAS DE CRISTO REY | C29: total | D29: Mandato | E29: Bogotá, D.C. | F29: Interes | G29: =SUMIFS('Enero Data'!C:C,'Enero Data'!A:A,B29,'Enero Data'!B:B,F29) -> 32062.42 | H29: =VLOOKUP(B29,'Enero Data'!A:D,4,FALSE) -> UESP1416 | I29: Cristo Rey
A30: Congregación De Religiosas Hijas De Cristo Rey | B30: CONGREGACIÓN DE RELIGIOSAS HIJAS DE CRISTO REY | C30: total | D30: Mandato | E30: Bogotá, D.C. | F30: Valor a Pagar | G30: =G29+G28 -> 2404829.2 | H30: =VLOOKUP(B30,'Enero Data'!A:D,4,FALSE) -> UESP1416
A31: Congregación De Religiosas Hijas De Cristo Rey | B31: CONGREGACIÓN DE RELIGIOSAS HIJAS DE CRISTO REY | C31: Factura | D31: Factura | F31: Administración | G31: =G30*5% -> 120241.46 | H31: =VLOOKUP(B31,'Enero Data'!A:D,4,FALSE) -> UESP1416
A32: Congregación De Religiosas Hijas De Cristo Rey | B32: CONGREGACIÓN DE RELIGIOSAS HIJAS DE CRISTO REY | C32: Factura | D32: Factura | F32: Total | G32: =G31 -> 120241.46 | H32: =VLOOKUP(B32,'Enero Data'!A:D,4,FALSE) -> UESP1416
A33: Conjunto Laureles Campestre Etapas I Ii Y Iii Ph | B33: CONJUNTO LAURELES CAMPESTRE ETAPAS I II Y III | C33: Total | D33: Mandato | E33: Medellín | F33: Ingreso Bruto | G33: =SUMIFS('Enero Data'!C:C,'Enero Data'!A:A,B33,'Enero Data'!B:B,F33) -> 0 | H33: =VLOOKUP(B33,'Enero Data'!A:D,4,FALSE) -> #N/A | I33: Laureles Campestre | J33: =J28+1 -> 410
A34: Conjunto Laureles Campestre Etapas I Ii Y Iii Ph | B34: CONJUNTO LAURELES CAMPESTRE ETAPAS I II Y III | C34: total | D34: Mandato | E34: Medellín | F34: Interes | G34: =SUMIFS('Enero Data'!C:C,'Enero Data'!A:A,B34,'Enero Data'!B:B,F34) -> 0 | H34: =VLOOKUP(B34,'Enero Data'!A:D,4,FALSE) -> #N/A | I34: Laureles Campestre
A35: Conjunto Laureles Campestre Etapas I Ii Y Iii Ph | B35: CONJUNTO LAURELES CAMPESTRE ETAPAS I II Y III | C35: total | D35: Mandato | E35: Medellín | F35: Valor a Pagar | G35: =G34+G33 -> 0 | H35: =VLOOKUP(B35,'Enero Data'!A:D,4,FALSE) -> #N/A
A36: Conjunto Laureles Campestre Etapas I Ii Y Iii Ph | B36: CONJUNTO LAURELES CAMPESTRE ETAPAS I II Y III | C36: Factura | D36: Factura | F36: Administración | G36: =G35*5% -> 0 | H36: =VLOOKUP(B36,'Enero Data'!A:D,4,FALSE) -> #N/A
A37: Conjunto Laureles Campestre Etapas I Ii Y Iii Ph | B37: CONJUNTO LAURELES CAMPESTRE ETAPAS I II Y III | C37: Factura | D37: Factura | F37: Total | G37: =G36 -> 0 | H37: =VLOOKUP(B37,'Enero Data'!A:D,4,FALSE) -> #N/A
A38: Conjunto Residencial San Esteban Del Poblado P.H. | B38: CONJUNTO RESIDENCIAL SAN ESTEBAN DEL POBLADO P.H. | C38: Total | D38: Mandato | E38: Medellín | F38: Ingreso Bruto | G38: =SUMIFS('Enero Data'!C:C,'Enero Data'!A:A,B38,'Enero Data'!B:B,F38) -> 1516423.9 | H38: =VLOOKUP(B38,'Enero Data'!A:D,4,FALSE) -> UESP1430 | I38: San Esteban | J38: =J33+1 -> 411
A39: Conjunto Residencial San Esteban Del Poblado P.H. | B39: CONJUNTO RESIDENCIAL SAN ESTEBAN DEL POBLADO P.H. | C39: total | D39: Mandato | E39: Medellín | F39: Interes | G39: =SUMIFS('Enero Data'!C:C,'Enero Data'!A:A,B39,'Enero Data'!B:B,F39) -> 10686.82 | H39: =VLOOKUP(B39,'Enero Data'!A:D,4,FALSE) -> UESP1430 | I39: San Esteban
A40: Conjunto Residencial San Esteban Del Poblado P.H. | B40: CONJUNTO RESIDENCIAL SAN ESTEBAN DEL POBLADO P.H. | C40: total | D40: Mandato | E40: Medellín | F40: Valor a Pagar | G40: =G39+G38 -> 1527110.7 | H40: =VLOOKUP(B40,'Enero Data'!A:D,4,FALSE) -> UESP1430
...

Sheet Febrero
A1: Proyecto | B1: CLIENTE | C1: Inversionista | D1: Documento contable | E1: Ciudad | F1: Concepto | G1: Total | H1: Factura | I1: Link Carpeta General | J1: Codigo | L1: Generar | M1: Proyecto | N1: Carpeta proyecto | O1: Factura | Q1: Fecha de Firma | R1: 46092 | S1: Fecha periodo | T1: 01 al 28 de febrero del 2026 | U1: consecutivo final | V1: 522
A2: Almacen Amc Sas | B2: ALMACEN AMC SAS | C2: Total | D2: Mandato | E2: Sincelejo | F2: Ingreso Bruto | G2: =SUMIFS('Febrero Data'!C:C,'Febrero Data'!A:A,B2,'Febrero Data'!B:B,F2) -> 3765456 | H2: =VLOOKUP(B2,'Febrero Data'!A:D,4,FALSE) -> UESP1526 | I2: AMC | J2: =V1 -> 522 | L2: TRUE | M2: Almacen Amc Sas | N2: AMC
A3: Almacen Amc Sas | B3: ALMACEN AMC SAS | C3: total | D3: Mandato | E3: Sincelejo | F3: Interes | G3: =SUMIFS('Febrero Data'!C:C,'Febrero Data'!A:A,B3,'Febrero Data'!B:B,F3) -> 153874.2 | H3: =VLOOKUP(B3,'Febrero Data'!A:D,4,FALSE) -> UESP1526 | I3: AMC | L3: TRUE
A4: Almacen Amc Sas | B4: ALMACEN AMC SAS | C4: total | D4: Mandato | E4: Sincelejo | F4: Valor a Pagar | G4: =G2+G3 -> 3919330.2 | H4: =VLOOKUP(B4,'Febrero Data'!A:D,4,FALSE) -> UESP1526 | L4: TRUE | M4: Central De Maderas G&S S.A.S. | N4: Central de maderas
A5: Almacen Amc Sas | B5: ALMACEN AMC SAS | C5: Factura | D5: Factura | E5: Sincelejo | F5: Administración | G5: =G4*5% -> 195966.51 | H5: =VLOOKUP(B5,'Febrero Data'!A:D,4,FALSE) -> UESP1526 | I5: AMC | L5: TRUE | M5: Centro Comercial Y Empresarial Obelisco - P.H.- | N5: Obelisco
A6: Almacen Amc Sas | B6: ALMACEN AMC SAS | C6: Factura | D6: Factura | E6: Sincelejo | F6: Total | G6: =G5 -> 195966.51 | H6: =VLOOKUP(B6,'Febrero Data'!A:D,4,FALSE) -> UESP1526 | I6: AMC | L6: TRUE | M6: Condominio Acanto P. H | N6: Acanto
A7: Arcillas San Simon S.A.S. | B7: ARCILLAS SAN SIMON S.A.S. | C7: Total | D7: Mandato | E7: El Zulia | F7: Ingreso Bruto | G7: =SUMIFS('Febrero Data'!C:C,'Febrero Data'!A:A,B7,'Febrero Data'!B:B,F7) -> 0 | H7: =VLOOKUP(B7,'Febrero Data'!A:D,4,FALSE) -> #N/A | I7: Arcillas San Simón | J7: =J2 -> 522 | L7: TRUE
A8: Arcillas San Simon S.A.S. | B8: ARCILLAS SAN SIMON S.A.S. | C8: total | D8: Mandato | E8: El Zulia | F8: Interes | G8: =SUMIFS('Febrero Data'!C:C,'Febrero Data'!A:A,B8,'Febrero Data'!B:B,F8) -> 0 | H8: =VLOOKUP(B8,'Febrero Data'!A:D,4,FALSE) -> #N/A | I8: Arcillas San Simón | L8: TRUE
A9: Arcillas San Simon S.A.S. | B9: ARCILLAS SAN SIMON S.A.S. | C9: total | D9: Mandato | E9: El Zulia | F9: Valor a Pagar | G9: =G8+G7 -> 0 | H9: =VLOOKUP(B9,'Febrero Data'!A:D,4,FALSE) -> #N/A | L9: TRUE
A10: Arcillas San Simon S.A.S. | B10: ARCILLAS SAN SIMON S.A.S. | C10: Factura | D10: Factura | E10: El Zulia | F10: Administración | G10: =G9*5% -> 0 | H10: =VLOOKUP(B10,'Febrero Data'!A:D,4,FALSE) -> #N/A | L10: TRUE
A11: Arcillas San Simon S.A.S. | B11: ARCILLAS SAN SIMON S.A.S. | C11: Factura | D11: Factura | E11: El Zulia | F11: Total | G11: =G10 -> 0 | H11: =VLOOKUP(B11,'Febrero Data'!A:D,4,FALSE) -> #N/A | L11: TRUE
A12: Central De Maderas G&S S.A.S. | B12: CENTRAL DE MADERAS G&S S.A.S. | C12: Total | D12: Mandato | E12: Turbaná | F12: Ingreso Bruto | G12: =SUMIFS('Febrero Data'!C:C,'Febrero Data'!A:A,B12,'Febrero Data'!B:B,F12) -> 3089496 | H12: =VLOOKUP(B12,'Febrero Data'!A:D,4,FALSE) -> UESP1534 | I12: Central de maderas | J12: =J2+1 -> 523 | L12: TRUE | M12: Congregación De Religiosas Hijas De Cristo Rey | N12: Cristo Rey
A13: Central De Maderas G&S S.A.S. | B13: CENTRAL DE MADERAS G&S S.A.S. | C13: total | D13: Mandato | E13: Turbaná | F13: Interes | G13: =SUMIFS('Febrero Data'!C:C,'Febrero Data'!A:A,B13,'Febrero Data'!B:B,F13) -> 15425.21 | H13: =VLOOKUP(B13,'Febrero Data'!A:D,4,FALSE) -> UESP1534 | I13: Central de maderas | L13: TRUE | M13: Conjunto Laureles Campestre Etapas I Ii Y Iii Ph | N13: Laureles Campestre
A14: Central De Maderas G&S S.A.S. | B14: CENTRAL DE MADERAS G&S S.A.S. | C14: total | D14: Mandato | F14: Retención en la fuente | G14: =(G12+G13)*4% -> 124196.85 | H14: =VLOOKUP(B14,'Febrero Data'!A:D,4,FALSE) -> UESP1534 | L14: TRUE | M14: Conjunto Residencial San Esteban Del Poblado P.H. | N14: San Esteban
A15: Central De Maderas G&S S.A.S. | B15: CENTRAL DE MADERAS G&S S.A.S. | C15: total | D15: Mandato | E15: Turbaná | F15: Valor a Pagar | G15: =G12+G13-G14 -> 2980724.4 | H15: =VLOOKUP(B15,'Febrero Data'!A:D,4,FALSE) -> UESP1534 | L15: TRUE | M15: Cooperativa Antioqueña De Salud | N15: coopsana ips
A16: Central De Maderas G&S S.A.S. | B16: CENTRAL DE MADERAS G&S S.A.S. | C16: Factura | D16: Factura | E16: Turbaná | F16: Administración | G16: =G15*5% -> 149036.22 | H16: =VLOOKUP(B16,'Febrero Data'!A:D,4,FALSE) -> UESP1534 | L16: TRUE | M16: Dual Cross S.A.S | N16: Cross Bisnes center
A17: Central De Maderas G&S S.A.S. | B17: CENTRAL DE MADERAS G&S S.A.S. | C17: Factura | D17: Factura | E17: Turbaná | F17: Total | G17: =G16 -> 149036.22 | H17: =VLOOKUP(B17,'Febrero Data'!A:D,4,FALSE) -> UESP1534 | L17: TRUE | M17: Ecoimagen Salud S.A.S | N17: Ecoimagen ips
A18: Centro Comercial Y Empresarial Obelisco - P.H.- | B18: CENTRO COMERCIAL Y EMPRESARIAL OBELISCO - P.H.- | C18: Total | D18: Mandato | E18: Medellín | F18: Ingreso Bruto | G18: =SUMIFS('Febrero Data'!C:C,'Febrero Data'!A:A,B18,'Febrero Data'!B:B,F18) -> 4884847 | H18: =VLOOKUP(B18,'Febrero Data'!A:D,4,FALSE) -> UESP1528 | I18: Obelisco | J18: =J12+1 -> 524 | L18: TRUE | M18: Edificio Torre Almagran Propiedad Horizontal | N18: Almagran
A19: Centro Comercial Y Empresarial Obelisco - P.H.- | B19: CENTRO COMERCIAL Y EMPRESARIAL OBELISCO - P.H.- | C19: total | D19: Mandato | E19: Medellín | F19: Interes | G19: =SUMIFS('Febrero Data'!C:C,'Febrero Data'!A:A,B19,'Febrero Data'!B:B,F19) -> 3515.89 | H19: =VLOOKUP(B19,'Febrero Data'!A:D,4,FALSE) -> UESP1528 | I19: Obelisco | L19: TRUE | M19: Instituto Bolivariano (Ibes) | N19: instituto bolivariano (ibes)
A20: Centro Comercial Y Empresarial Obelisco - P.H.- | B20: CENTRO COMERCIAL Y EMPRESARIAL OBELISCO - P.H.- | C20: total | D20: Mandato | E20: Medellín | F20: Valor a Pagar | G20: =G19+G18 -> 4888362.9 | H20: =VLOOKUP(B20,'Febrero Data'!A:D,4,FALSE) -> UESP1528 | L20: TRUE | M20: Los Coches | N20: Hotel los coches
A21: Centro Comercial Y Empresarial Obelisco - P.H.- | B21: CENTRO COMERCIAL Y EMPRESARIAL OBELISCO - P.H.- | C21: Factura | D21: Factura | F21: Administración | G21: =G20*5% -> 244418.14 | H21: =VLOOKUP(B21,'Febrero Data'!A:D,4,FALSE) -> UESP1528 | L21: TRUE | M21: M.D.M. Cientifica S.A.S | N21: MDM Cientifica
A22: Centro Comercial Y Empresarial Obelisco - P.H.- | B22: CENTRO COMERCIAL Y EMPRESARIAL OBELISCO - P.H.- | C22: Factura | D22: Factura | F22: Total | G22: =G21 -> 244418.14 | H22: =VLOOKUP(B22,'Febrero Data'!A:D,4,FALSE) -> UESP1528 | L22: TRUE | M22: Polikem S.A.S | N22: Polikem
A23: Condominio Acanto P. H | B23: CONDOMINIO ACANTO Ρ. Η | C23: Total | D23: Mandato | E23: Envigado | F23: Ingreso Bruto | G23: =SUMIFS('Febrero Data'!C:C,'Febrero Data'!A:A,B23,'Febrero Data'!B:B,F23) -> 4271092 | H23: =VLOOKUP(B23,'Febrero Data'!A:D,4,FALSE) -> UESP1524 | I23: Acanto | J23: =J18+1 -> 525 | L23: TRUE | M23: Servicios Industriales Y Metalmecanicos Sas | N23: Seridme
A24: Condominio Acanto P. H | B24: CONDOMINIO ACANTO Ρ. Η | C24: total | D24: Mandato | E24: Envigado | F24: Interes | G24: =SUMIFS('Febrero Data'!C:C,'Febrero Data'!A:A,B24,'Febrero Data'!B:B,F24) -> 0 | H24: =VLOOKUP(B24,'Febrero Data'!A:D,4,FALSE) -> UESP1524 | I24: Acanto | L24: TRUE | M24: Sociedad Educativa Ngs Sas | N24: NGS
A25: Condominio Acanto P. H | B25: CONDOMINIO ACANTO Ρ. Η | C25: total | D25: Mandato | E25: Envigado | F25: Valor a Pagar | G25: =G24+G23 -> 4271092 | H25: =VLOOKUP(B25,'Febrero Data'!A:D,4,FALSE) -> UESP1524 | L25: TRUE | M25: Sociedad Medica Rionegro S.A. Somer S.A. | N25: Clinica Somer
A26: Condominio Acanto P. H | B26: CONDOMINIO ACANTO Ρ. Η | C26: Factura | D26: Factura | F26: Administración | G26: =G25*5% -> 213554.6 | H26: =VLOOKUP(B26,'Febrero Data'!A:D,4,FALSE) -> UESP1524 | L26: TRUE | M26: The Pub S. A. S. | N26: Pola Del Pub
A27: Condominio Acanto P. H | B27: CONDOMINIO ACANTO Ρ. Η | C27: Factura | D27: Factura | F27: Total | G27: =G26 -> 213554.6 | H27: =VLOOKUP(B27,'Febrero Data'!A:D,4,FALSE) -> UESP1524 | L27: TRUE | M27: Urbanizacion Arboleda De Castilla Propiedad Horizontal | N27: arboleda de castilla
A28: Congregación De Religiosas Hijas De Cristo Rey | B28: CONGREGACIÓN DE RELIGIOSAS HIJAS DE CRISTO REY | C28: Total | D28: Mandato | E28: Bogotá, D.C. | F28: Ingreso Bruto | G28: =SUMIFS('Febrero Data'!C:C,'Febrero Data'!A:A,B28,'Febrero Data'!B:B,F28) -> 2244451 | H28: =VLOOKUP(B28,'Febrero Data'!A:D,4,FALSE) -> UESP1519 | I28: Cristo Rey | J28: =J23+1 -> 526
A29: Congregación De Religiosas Hijas De Cristo Rey | B29: CONGREGACIÓN DE RELIGIOSAS HIJAS DE CRISTO REY | C29: total | D29: Mandato | E29: Bogotá, D.C. | F29: Interes | G29: =SUMIFS('Febrero Data'!C:C,'Febrero Data'!A:A,B29,'Febrero Data'!B:B,F29) -> 53672.5 | H29: =VLOOKUP(B29,'Febrero Data'!A:D,4,FALSE) -> UESP1519 | I29: Cristo Rey
A30: Congregación De Religiosas Hijas De Cristo Rey | B30: CONGREGACIÓN DE RELIGIOSAS HIJAS DE CRISTO REY | C30: total | D30: Mandato | E30: Bogotá, D.C. | F30: Valor a Pagar | G30: =G29+G28 -> 2298123.5 | H30: =VLOOKUP(B30,'Febrero Data'!A:D,4,FALSE) -> UESP1519
A31: Congregación De Religiosas Hijas De Cristo Rey | B31: CONGREGACIÓN DE RELIGIOSAS HIJAS DE CRISTO REY | C31: Factura | D31: Factura | F31: Administración | G31: =G30*5% -> 114906.18 | H31: =VLOOKUP(B31,'Febrero Data'!A:D,4,FALSE) -> UESP1519
A32: Congregación De Religiosas Hijas De Cristo Rey | B32: CONGREGACIÓN DE RELIGIOSAS HIJAS DE CRISTO REY | C32: Factura | D32: Factura | F32: Total | G32: =G31 -> 114906.18 | H32: =VLOOKUP(B32,'Febrero Data'!A:D,4,FALSE) -> UESP1519
A33: Conjunto Laureles Campestre Etapas I Ii Y Iii Ph | B33: CONJUNTO LAURELES CAMPESTRE ETAPAS I II Y III | C33: Total | D33: Mandato | E33: Medellín | F33: Ingreso Bruto | G33: =SUMIFS('Febrero Data'!C:C,'Febrero Data'!A:A,B33,'Febrero Data'!B:B,F33) -> 11561704 | H33: =VLOOKUP(B33,'Febrero Data'!A:D,4,FALSE) -> UESP1539 | I33: Laureles Campestre | J33: =J28+1 -> 527
A34: Conjunto Laureles Campestre Etapas I Ii Y Iii Ph | B34: CONJUNTO LAURELES CAMPESTRE ETAPAS I II Y III | C34: total | D34: Mandato | E34: Medellín | F34: Interes | G34: =SUMIFS('Febrero Data'!C:C,'Febrero Data'!A:A,B34,'Febrero Data'!B:B,F34) -> 171219.46 | H34: =VLOOKUP(B34,'Febrero Data'!A:D,4,FALSE) -> UESP1539 | I34: Laureles Campestre
A35: Conjunto Laureles Campestre Etapas I Ii Y Iii Ph | B35: CONJUNTO LAURELES CAMPESTRE ETAPAS I II Y III | C35: total | D35: Mandato | E35: Medellín | F35: Valor a Pagar | G35: =G34+G33 -> 11732924 | H35: =VLOOKUP(B35,'Febrero Data'!A:D,4,FALSE) -> UESP1539
A36: Conjunto Laureles Campestre Etapas I Ii Y Iii Ph | B36: CONJUNTO LAURELES CAMPESTRE ETAPAS I II Y III | C36: Factura | D36: Factura | F36: Administración | G36: =G35*5% -> 586646.2 | H36: =VLOOKUP(B36,'Febrero Data'!A:D,4,FALSE) -> UESP1539
A37: Conjunto Laureles Campestre Etapas I Ii Y Iii Ph | B37: CONJUNTO LAURELES CAMPESTRE ETAPAS I II Y III | C37: Factura | D37: Factura | F37: Total | G37: =G36 -> 586646.2 | H37: =VLOOKUP(B37,'Febrero Data'!A:D,4,FALSE) -> UESP1539
A38: Conjunto Residencial San Esteban Del Poblado P.H. | B38: CONJUNTO RESIDENCIAL SAN ESTEBAN DEL POBLADO P.H. | C38: Total | D38: Mandato | E38: Medellín | F38: Ingreso Bruto | G38: =SUMIFS('Febrero Data'!C:C,'Febrero Data'!A:A,B38,'Febrero Data'!B:B,F38) -> 1609725 | H38: =VLOOKUP(B38,'Febrero Data'!A:D,4,FALSE) -> UESP1529 | I38: San Esteban | J38: =J33+1 -> 528
A39: Conjunto Residencial San Esteban Del Poblado P.H. | B39: CONJUNTO RESIDENCIAL SAN ESTEBAN DEL POBLADO P.H. | C39: total | D39: Mandato | E39: Medellín | F39: Interes | G39: =SUMIFS('Febrero Data'!C:C,'Febrero Data'!A:A,B39,'Febrero Data'!B:B,F39) -> 20928.27 | H39: =VLOOKUP(B39,'Febrero Data'!A:D,4,FALSE) -> UESP1529 | I39: San Esteban
A40: Conjunto Residencial San Esteban Del Poblado P.H. | B40: CONJUNTO RESIDENCIAL SAN ESTEBAN DEL POBLADO P.H. | C40: total | D40: Mandato | E40: Medellín | F40: Valor a Pagar | G40: =G39+G38 -> 1630653.3 | H40: =VLOOKUP(B40,'Febrero Data'!A:D,4,FALSE) -> UESP1529
...

Sheet Marzo
A1: Proyecto | B1: CLIENTE | C1: Inversionista | D1: Documento contable | E1: Ciudad | F1: Concepto | G1: Total | H1: Factura | I1: ID ODOO | J1: Codigo | L1: Generar | M1: Proyecto | N1: Carpeta proyecto | O1: Factura | Q1: Fecha de Firma | R1: 46123 | S1: Fecha periodo | T1: 01 al 31 de marzo del 2026 | U1: consecutivo final | V1: 642
A2: Almacen Amc Sas | B2: ALMACEN AMC SAS | C2: Total | D2: Mandato | E2: Sincelejo | F2: Ingreso Bruto | G2: =SUMIFS('Marzo Data'!C:C,'Marzo Data'!A:A,B2,'Marzo Data'!B:B,F2) -> 4861937.7 | H2: =VLOOKUP(B2,'Marzo Data'!A:D,4,FALSE) -> UESP1658 | I2: ALMACEN AMC SAS | J2: =V1 -> 642 | L2: FALSE | M2: Almacen Amc Sas | N2: AMC
A3: Almacen Amc Sas | B3: ALMACEN AMC SAS | C3: total | D3: Mandato | E3: Sincelejo | F3: Interes | G3: =SUMIFS('Marzo Data'!C:C,'Marzo Data'!A:A,B3,'Marzo Data'!B:B,F3) -> 241991.07 | H3: =VLOOKUP(B3,'Marzo Data'!A:D,4,FALSE) -> UESP1658 | I3: ALMACEN AMC SAS | L3: FALSE
A4: Almacen Amc Sas | B4: ALMACEN AMC SAS | C4: total | D4: Mandato | E4: Sincelejo | F4: Valor a Pagar | G4: =G2+G3 -> 5103928.8 | H4: =VLOOKUP(B4,'Marzo Data'!A:D,4,FALSE) -> UESP1658 | L4: FALSE | M4: Central De Maderas G&S S.A.S. | N4: Central de maderas
A5: Almacen Amc Sas | B5: ALMACEN AMC SAS | C5: Factura | D5: Factura | E5: Sincelejo | F5: Administración | G5: =G4*5% -> 255196.44 | H5: =VLOOKUP(B5,'Marzo Data'!A:D,4,FALSE) -> UESP1658 | I5: ALMACEN AMC SAS | L5: FALSE | M5: Centro Comercial Y Empresarial Obelisco - P.H.- | N5: Obelisco
A6: Almacen Amc Sas | B6: ALMACEN AMC SAS | C6: Factura | D6: Factura | E6: Sincelejo | F6: Total | G6: =G5 -> 255196.44 | H6: =VLOOKUP(B6,'Marzo Data'!A:D,4,FALSE) -> UESP1658 | I6: ALMACEN AMC SAS | L6: FALSE | M6: Condominio Acanto P. H | N6: Acanto
A7: Arcillas San Simon S.A.S. | B7: ARCILLAS SAN SIMON S.A.S. | C7: Total | D7: Mandato | E7: El Zulia | F7: Mantenimiento CENS | G7: 76359129 | H7: =VLOOKUP(B7,'Marzo Data'!A:D,4,FALSE) -> #N/A | J7: 759 | L7: FALSE
A8: Arcillas San Simon S.A.S. | B8: ARCILLAS SAN SIMON S.A.S. | C8: total | D8: Mandato | E8: El Zulia | F8: Interes | G8: =SUMIFS('Marzo Data'!C:C,'Marzo Data'!A:A,B8,'Marzo Data'!B:B,F8) -> 0 | H8: =VLOOKUP(B8,'Marzo Data'!A:D,4,FALSE) -> #N/A | L8: TRUE | M8: Arcillas San Simon S.A.S.
A9: Arcillas San Simon S.A.S. | B9: ARCILLAS SAN SIMON S.A.S. | C9: total | D9: Mandato | E9: El Zulia | F9: Valor a Pagar | G9: =G8+G7 -> 76359129 | H9: =VLOOKUP(B9,'Marzo Data'!A:D,4,FALSE) -> #N/A | L9: FALSE
A10: Arcillas San Simon S.A.S. | B10: ARCILLAS SAN SIMON S.A.S. | C10: Factura | D10: Factura | E10: El Zulia | F10: Administración | G10: =G9*5% -> 3817956.5 | H10: =VLOOKUP(B10,'Marzo Data'!A:D,4,FALSE) -> #N/A | L10: FALSE
A11: Arcillas San Simon S.A.S. | B11: ARCILLAS SAN SIMON S.A.S. | C11: Factura | D11: Factura | E11: El Zulia | F11: Total | G11: =G10 -> 3817956.5 | H11: =VLOOKUP(B11,'Marzo Data'!A:D,4,FALSE) -> #N/A | L11: FALSE
A12: Central De Maderas G&S S.A.S. | B12: CENTRAL DE MADERAS G&S S.A.S. | C12: Total | D12: Mandato | E12: Turbaná | F12: Ingreso Bruto | G12: =SUMIFS('Marzo Data'!C:C,'Marzo Data'!A:A,B12,'Marzo Data'!B:B,F12) -> 4058738.2 | H12: =VLOOKUP(B12,'Marzo Data'!A:D,4,FALSE) -> UESP1665 | I12: CENTRAL DE MADERAS G&S SAS | J12: =J2+1 -> 643 | L12: FALSE | M12: Congregación De Religiosas Hijas De Cristo Rey | N12: Cristo Rey
A13: Central De Maderas G&S S.A.S. | B13: CENTRAL DE MADERAS G&S S.A.S. | C13: total | D13: Mandato | E13: Turbaná | F13: Interes | G13: =SUMIFS('Marzo Data'!C:C,'Marzo Data'!A:A,B13,'Marzo Data'!B:B,F13) -> 49606.16 | H13: =VLOOKUP(B13,'Marzo Data'!A:D,4,FALSE) -> UESP1665 | I13: CENTRAL DE MADERAS G&S SAS | L13: FALSE | M13: Conjunto Laureles Campestre Etapas I Ii Y Iii Ph | N13: Laureles Campestre
A14: Central De Maderas G&S S.A.S. | B14: CENTRAL DE MADERAS G&S S.A.S. | C14: total | D14: Mandato | F14: Retención en la fuente | G14: =(G12+G13)*4% -> 164333.77 | H14: =VLOOKUP(B14,'Marzo Data'!A:D,4,FALSE) -> UESP1665 | I14: CENTRAL DE MADERAS G&S SAS | L14: FALSE | M14: Conjunto Residencial San Esteban Del Poblado P.H. | N14: San Esteban
A15: Central De Maderas G&S S.A.S. | B15: CENTRAL DE MADERAS G&S S.A.S. | C15: total | D15: Mandato | E15: Turbaná | F15: Valor a Pagar | G15: =G12+G13-G14 -> 3944010.6 | H15: =VLOOKUP(B15,'Marzo Data'!A:D,4,FALSE) -> UESP1665 | L15: FALSE | M15: Cooperativa Antioqueña De Salud | N15: coopsana ips
A16: Central De Maderas G&S S.A.S. | B16: CENTRAL DE MADERAS G&S S.A.S. | C16: Factura | D16: Factura | E16: Turbaná | F16: Administración | G16: =G15*5% -> 197200.53 | H16: =VLOOKUP(B16,'Marzo Data'!A:D,4,FALSE) -> UESP1665 | I16: CENTRAL DE MADERAS G&S SAS | L16: FALSE | M16: Dual Cross S.A.S | N16: Cross Bisnes center
A17: Central De Maderas G&S S.A.S. | B17: CENTRAL DE MADERAS G&S S.A.S. | C17: Factura | D17: Factura | E17: Turbaná | F17: Total | G17: =G16 -> 197200.53 | H17: =VLOOKUP(B17,'Marzo Data'!A:D,4,FALSE) -> UESP1665 | I17: CENTRAL DE MADERAS G&S SAS | L17: FALSE | M17: Ecoimagen Salud S.A.S | N17: Ecoimagen ips
A18: Centro Comercial Y Empresarial Obelisco - P.H.- | B18: CENTRO COMERCIAL Y EMPRESARIAL OBELISCO - P.H.- | C18: Total | D18: Mandato | E18: Medellín | F18: Ingreso Bruto | G18: =SUMIFS('Marzo Data'!C:C,'Marzo Data'!A:A,B18,'Marzo Data'!B:B,F18) -> 7222564.5 | H18: =VLOOKUP(B18,'Marzo Data'!A:D,4,FALSE) -> UESP1660 | I18: CENTRO COMERCIAL Y EMPRESARIAL OBELISCO -P.H.- | J18: =J12+1 -> 644 | L18: FALSE | M18: Edificio Torre Almagran Propiedad Horizontal | N18: Almagran
A19: Centro Comercial Y Empresarial Obelisco - P.H.- | B19: CENTRO COMERCIAL Y EMPRESARIAL OBELISCO - P.H.- | C19: total | D19: Mandato | E19: Medellín | F19: Interes | G19: =SUMIFS('Marzo Data'!C:C,'Marzo Data'!A:A,B19,'Marzo Data'!B:B,F19) -> 0 | H19: =VLOOKUP(B19,'Marzo Data'!A:D,4,FALSE) -> UESP1660 | I19: CENTRO COMERCIAL Y EMPRESARIAL OBELISCO -P.H.- | L19: FALSE | M19: Instituto Bolivariano (Ibes) | N19: instituto bolivariano (ibes)
A20: Centro Comercial Y Empresarial Obelisco - P.H.- | B20: CENTRO COMERCIAL Y EMPRESARIAL OBELISCO - P.H.- | C20: total | D20: Mandato | E20: Medellín | F20: Valor a Pagar | G20: =G19+G18 -> 7222564.5 | H20: =VLOOKUP(B20,'Marzo Data'!A:D,4,FALSE) -> UESP1660 | L20: FALSE | M20: Los Coches | N20: Hotel los coches
A21: Centro Comercial Y Empresarial Obelisco - P.H.- | B21: CENTRO COMERCIAL Y EMPRESARIAL OBELISCO - P.H.- | C21: Factura | D21: Factura | F21: Administración | G21: =G20*5% -> 361128.22 | H21: =VLOOKUP(B21,'Marzo Data'!A:D,4,FALSE) -> UESP1660 | I21: CENTRO COMERCIAL Y EMPRESARIAL OBELISCO -P.H.- | L21: FALSE | M21: M.D.M. Cientifica S.A.S | N21: MDM Cientifica
A22: Centro Comercial Y Empresarial Obelisco - P.H.- | B22: CENTRO COMERCIAL Y EMPRESARIAL OBELISCO - P.H.- | C22: Factura | D22: Factura | F22: Total | G22: =G21 -> 361128.22 | H22: =VLOOKUP(B22,'Marzo Data'!A:D,4,FALSE) -> UESP1660 | I22: CENTRO COMERCIAL Y EMPRESARIAL OBELISCO -P.H.- | L22: FALSE | M22: Polikem S.A.S | N22: Polikem
A23: Condominio Acanto P. H | B23: CONDOMINIO ACANTO Ρ. Η | C23: Total | D23: Mandato | E23: Envigado | F23: Ingreso Bruto | G23: =SUMIFS('Marzo Data'!C:C,'Marzo Data'!A:A,B23,'Marzo Data'!B:B,F23) -> 6007095 | H23: =VLOOKUP(B23,'Marzo Data'!A:D,4,FALSE) -> UESP1656 | I23: CONDOMINIO ACANTO P. H | J23: =J18+1 -> 645 | L23: FALSE | M23: Servicios Industriales Y Metalmecanicos Sas | N23: Seridme
A24: Condominio Acanto P. H | B24: CONDOMINIO ACANTO Ρ. Η | C24: total | D24: Mandato | E24: Envigado | F24: Interes | G24: =SUMIFS('Marzo Data'!C:C,'Marzo Data'!A:A,B24,'Marzo Data'!B:B,F24) -> 0 | H24: =VLOOKUP(B24,'Marzo Data'!A:D,4,FALSE) -> UESP1656 | I24: CONDOMINIO ACANTO P. H | L24: FALSE | M24: Sociedad Educativa Ngs Sas | N24: NGS
A25: Condominio Acanto P. H | B25: CONDOMINIO ACANTO Ρ. Η | C25: total | D25: Mandato | E25: Envigado | F25: Valor a Pagar | G25: =G24+G23 -> 6007095 | H25: =VLOOKUP(B25,'Marzo Data'!A:D,4,FALSE) -> UESP1656 | L25: FALSE | M25: Sociedad Medica Rionegro S.A. Somer S.A. | N25: Clinica Somer
A26: Condominio Acanto P. H | B26: CONDOMINIO ACANTO Ρ. Η | C26: Factura | D26: Factura | F26: Administración | G26: =G25*5% -> 300354.75 | H26: =VLOOKUP(B26,'Marzo Data'!A:D,4,FALSE) -> UESP1656 | I26: CONDOMINIO ACANTO P. H | L26: FALSE | M26: The Pub S. A. S. | N26: Pola Del Pub
A27: Condominio Acanto P. H | B27: CONDOMINIO ACANTO Ρ. Η | C27: Factura | D27: Factura | F27: Total | G27: =G26 -> 300354.75 | H27: =VLOOKUP(B27,'Marzo Data'!A:D,4,FALSE) -> UESP1656 | I27: CONDOMINIO ACANTO P. H | L27: FALSE | M27: Urbanizacion Arboleda De Castilla Propiedad Horizontal | N27: arboleda de castilla
A28: Congregación De Religiosas Hijas De Cristo Rey | B28: CONGREGACIÓN DE RELIGIOSAS HIJAS DE CRISTO REY | C28: Total | D28: Mandato | E28: Bogotá, D.C. | F28: Ingreso Bruto | G28: =SUMIFS('Marzo Data'!C:C,'Marzo Data'!A:A,B28,'Marzo Data'!B:B,F28) -> 2558003.3 | H28: =VLOOKUP(B28,'Marzo Data'!A:D,4,FALSE) -> UESP1651 | I28: CONGREGACIÓN DE RELIGIOSAS HIJAS DE CRISTO REY | J28: =J23+1 -> 646
A29: Congregación De Religiosas Hijas De Cristo Rey | B29: CONGREGACIÓN DE RELIGIOSAS HIJAS DE CRISTO REY | C29: total | D29: Mandato | E29: Bogotá, D.C. | F29: Interes | G29: =SUMIFS('Marzo Data'!C:C,'Marzo Data'!A:A,B29,'Marzo Data'!B:B,F29) -> 85515.56 | H29: =VLOOKUP(B29,'Marzo Data'!A:D,4,FALSE) -> UESP1651 | I29: CONGREGACIÓN DE RELIGIOSAS HIJAS DE CRISTO REY
A30: Congregación De Religiosas Hijas De Cristo Rey | B30: CONGREGACIÓN DE RELIGIOSAS HIJAS DE CRISTO REY | C30: total | D30: Mandato | E30: Bogotá, D.C. | F30: Valor a Pagar | G30: =G29+G28 -> 2643518.9 | H30: =VLOOKUP(B30,'Marzo Data'!A:D,4,FALSE) -> UESP1651
A31: Congregación De Religiosas Hijas De Cristo Rey | B31: CONGREGACIÓN DE RELIGIOSAS HIJAS DE CRISTO REY | C31: Factura | D31: Factura | F31: Administración | G31: =G30*5% -> 132175.94 | H31: =VLOOKUP(B31,'Marzo Data'!A:D,4,FALSE) -> UESP1651 | I31: CONGREGACIÓN DE RELIGIOSAS HIJAS DE CRISTO REY
A32: Congregación De Religiosas Hijas De Cristo Rey | B32: CONGREGACIÓN DE RELIGIOSAS HIJAS DE CRISTO REY | C32: Factura | D32: Factura | F32: Total | G32: =G31 -> 132175.94 | H32: =VLOOKUP(B32,'Marzo Data'!A:D,4,FALSE) -> UESP1651 | I32: CONGREGACIÓN DE RELIGIOSAS HIJAS DE CRISTO REY
A33: Conjunto Laureles Campestre Etapas I Ii Y Iii Ph | B33: CONJUNTO LAURELES CAMPESTRE ETAPAS I II Y III | C33: Total | D33: Mandato | E33: Medellín | F33: Ingreso Bruto | G33: =SUMIFS('Marzo Data'!C:C,'Marzo Data'!A:A,B33,'Marzo Data'!B:B,F33) -> 14787227 | H33: =VLOOKUP(B33,'Marzo Data'!A:D,4,FALSE) -> UESP1668 | I33: CONJUNTO LAURELES CAMPESTRE ETAPAS I II Y III PH | J33: =J28+1 -> 647
A34: Conjunto Laureles Campestre Etapas I Ii Y Iii Ph | B34: CONJUNTO LAURELES CAMPESTRE ETAPAS I II Y III | C34: total | D34: Mandato | E34: Medellín | F34: Interes | G34: =SUMIFS('Marzo Data'!C:C,'Marzo Data'!A:A,B34,'Marzo Data'!B:B,F34) -> 374604.73 | H34: =VLOOKUP(B34,'Marzo Data'!A:D,4,FALSE) -> UESP1668 | I34: CONJUNTO LAURELES CAMPESTRE ETAPAS I II Y III PH
A35: Conjunto Laureles Campestre Etapas I Ii Y Iii Ph | B35: CONJUNTO LAURELES CAMPESTRE ETAPAS I II Y III | C35: total | D35: Mandato | E35: Medellín | F35: Valor a Pagar | G35: =G34+G33 -> 15161832 | H35: =VLOOKUP(B35,'Marzo Data'!A:D,4,FALSE) -> UESP1668
A36: Conjunto Laureles Campestre Etapas I Ii Y Iii Ph | B36: CONJUNTO LAURELES CAMPESTRE ETAPAS I II Y III | C36: Factura | D36: Factura | F36: Administración | G36: =G35*5% -> 758091.6 | H36: =VLOOKUP(B36,'Marzo Data'!A:D,4,FALSE) -> UESP1668 | I36: CONJUNTO LAURELES CAMPESTRE ETAPAS I II Y III PH
A37: Conjunto Laureles Campestre Etapas I Ii Y Iii Ph | B37: CONJUNTO LAURELES CAMPESTRE ETAPAS I II Y III | C37: Factura | D37: Factura | F37: Total | G37: =G36 -> 758091.6 | H37: =VLOOKUP(B37,'Marzo Data'!A:D,4,FALSE) -> UESP1668 | I37: CONJUNTO LAURELES CAMPESTRE ETAPAS I II Y III PH
A38: Conjunto Residencial San Esteban Del Poblado P.H. | B38: CONJUNTO RESIDENCIAL SAN ESTEBAN DEL POBLADO P.H. | C38: Total | D38: Mandato | E38: Medellín | F38: Ingreso Bruto | G38: =SUMIFS('Marzo Data'!C:C,'Marzo Data'!A:A,B38,'Marzo Data'!B:B,F38) -> 2586674.1 | H38: =VLOOKUP(B38,'Marzo Data'!A:D,4,FALSE) -> UESP1667 | I38: CONJUNTO RESIDENCIAL SAN ESTEBAN DEL POBLADO P.H. | J38: =J33+1 -> 648
A39: Conjunto Residencial San Esteban Del Poblado P.H. | B39: CONJUNTO RESIDENCIAL SAN ESTEBAN DEL POBLADO P.H. | C39: total | D39: Mandato | E39: Medellín | F39: Interes | G39: =SUMIFS('Marzo Data'!C:C,'Marzo Data'!A:A,B39,'Marzo Data'!B:B,F39) -> 33127.11 | H39: =VLOOKUP(B39,'Marzo Data'!A:D,4,FALSE) -> UESP1667 | I39: CONJUNTO RESIDENCIAL SAN ESTEBAN DEL POBLADO P.H.
A40: Conjunto Residencial San Esteban Del Poblado P.H. | B40: CONJUNTO RESIDENCIAL SAN ESTEBAN DEL POBLADO P.H. | C40: total | D40: Mandato | E40: Medellín | F40: Valor a Pagar | G40: =G39+G38 -> 2619801.2 | H40: =VLOOKUP(B40,'Marzo Data'!A:D,4,FALSE) -> UESP1667
...

Sheet Abril
A1: Proyecto | B1: CLIENTE | C1: Inversionista | D1: Documento contable | E1: Ciudad | F1: Concepto | G1: Total | H1: Factura | I1: ID ODOO | J1: Codigo | L1: Generar | M1: Proyecto | N1: Carpeta proyecto | O1: Factura | Q1: Fecha de Firma | R1: 46155 | S1: Fecha periodo | T1: 01 al 31 de abril del 2026 | U1: consecutivo final | V1: 769
A2: Almacen Amc Sas | B2: ALMACEN AMC SAS | C2: Total | D2: Mandato | E2: Sincelejo | F2: Ingreso Bruto | G2: =SUMIFS('Abril Data'!C:C,'Abril Data'!A:A,B2,'Abril Data'!B:B,F2) -> 4667178.4 | H2: =VLOOKUP(B2,'Abril Data'!A:D,4,FALSE) -> UESP1772 | I2: ALMACEN AMC SAS | J2: =V1 -> 769 | L2: TRUE | M2: Almacen Amc Sas | N2: AMC
A3: Almacen Amc Sas | B3: ALMACEN AMC SAS | C3: total | D3: Mandato | E3: Sincelejo | F3: Interes | G3: =SUMIFS('Abril Data'!C:C,'Abril Data'!A:A,B3,'Abril Data'!B:B,F3) -> 186419.25 | H3: =VLOOKUP(B3,'Abril Data'!A:D,4,FALSE) -> UESP1772 | I3: ALMACEN AMC SAS | L3: TRUE
